<?xml version="1.0" ?>
<robot name="partnet_2bdedc5d70cda02cc59350d819542ec7">
	<link name="base">
		<inertial>
			<origin xyz="0 0 0"/>
			<mass value="0.01"/>
			<inertia ixx="0.0001" ixy="0" ixz="0" iyy="0.0001" iyz="0" izz="0.0001"/>
		</inertial>
	</link>
	<link name="link_0">
		<visual name="drawer_front-31">
			<origin xyz="0.009567187752129709 0.435532604741988 -0.3665049970149996"/>
			<geometry>
				<mesh filename="textured_objs/original-63.obj"/>
			</geometry>
		</visual>
		<visual name="drawer_front-31">
			<origin xyz="0.009567187752129709 0.435532604741988 -0.3665049970149996"/>
			<geometry>
				<mesh filename="textured_objs/original-60.obj"/>
			</geometry>
		</visual>
		<visual name="drawer_front-31">
			<origin xyz="0.009567187752129709 0.435532604741988 -0.3665049970149996"/>
			<geometry>
				<mesh filename="textured_objs/original-59.obj"/>
			</geometry>
		</visual>
		<visual name="drawer_front-31">
			<origin xyz="0.009567187752129709 0.435532604741988 -0.3665049970149996"/>
			<geometry>
				<mesh filename="textured_objs/original-58.obj"/>
			</geometry>
		</visual>
		<visual name="drawer_front-31">
			<origin xyz="0.009567187752129709 0.435532604741988 -0.3665049970149996"/>
			<geometry>
				<mesh filename="textured_objs/original-57.obj"/>
			</geometry>
		</visual>
		<visual name="drawer_front-31">
			<origin xyz="0.009567187752129709 0.435532604741988 -0.3665049970149996"/>
			<geometry>
				<mesh filename="textured_objs/original-62.obj"/>
			</geometry>
		</visual>
		<visual name="drawer_front-31">
			<origin xyz="0.009567187752129709 0.435532604741988 -0.3665049970149996"/>
			<geometry>
				<mesh filename="textured_objs/original-49.obj"/>
			</geometry>
		</visual>
		<visual name="drawer_side-32">
			<origin xyz="0.009567187752129709 0.435532604741988 -0.3665049970149996"/>
			<geometry>
				<mesh filename="textured_objs/original-48.obj"/>
			</geometry>
		</visual>
		<visual name="drawer_side-33">
			<origin xyz="0.009567187752129709 0.435532604741988 -0.3665049970149996"/>
			<geometry>
				<mesh filename="textured_objs/original-53.obj"/>
			</geometry>
		</visual>
		<visual name="drawer_side-33">
			<origin xyz="0.009567187752129709 0.435532604741988 -0.3665049970149996"/>
			<geometry>
				<mesh filename="textured_objs/original-55.obj"/>
			</geometry>
		</visual>
		<visual name="drawer_back-34">
			<origin xyz="0.009567187752129709 0.435532604741988 -0.3665049970149996"/>
			<geometry>
				<mesh filename="textured_objs/original-54.obj"/>
			</geometry>
		</visual>
		<visual name="drawer_bottom-35">
			<origin xyz="0.009567187752129709 0.435532604741988 -0.3665049970149996"/>
			<geometry>
				<mesh filename="textured_objs/original-52.obj"/>
			</geometry>
		</visual>
		<visual name="drawer_bottom-35">
			<origin xyz="0.009567187752129709 0.435532604741988 -0.3665049970149996"/>
			<geometry>
				<mesh filename="textured_objs/original-51.obj"/>
			</geometry>
		</visual>
		<visual name="handle-30">
			<origin xyz="0.009567187752129709 0.435532604741988 -0.3665049970149996"/>
			<geometry>
				<mesh filename="textured_objs/original-65.obj"/>
			</geometry>
		</visual>
		<visual name="handle-30">
			<origin xyz="0.009567187752129709 0.435532604741988 -0.3665049970149996"/>
			<geometry>
				<mesh filename="textured_objs/original-66.obj"/>
			</geometry>
		</visual>
		<visual name="handle-30">
			<origin xyz="0.009567187752129709 0.435532604741988 -0.3665049970149996"/>
			<geometry>
				<mesh filename="textured_objs/original-67.obj"/>
			</geometry>
		</visual>
		<collision>
			<origin xyz="0.009567187752129709 0.435532604741988 -0.3665049970149996"/>
			<geometry>
				<mesh filename="textured_objs/original-63.obj"/>
			</geometry>
		</collision>
		<collision>
			<origin xyz="0.009567187752129709 0.435532604741988 -0.3665049970149996"/>
			<geometry>
				<mesh filename="textured_objs/original-60.obj"/>
			</geometry>
		</collision>
		<collision>
			<origin xyz="0.009567187752129709 0.435532604741988 -0.3665049970149996"/>
			<geometry>
				<mesh filename="textured_objs/original-59.obj"/>
			</geometry>
		</collision>
		<collision>
			<origin xyz="0.009567187752129709 0.435532604741988 -0.3665049970149996"/>
			<geometry>
				<mesh filename="textured_objs/original-58.obj"/>
			</geometry>
		</collision>
		<collision>
			<origin xyz="0.009567187752129709 0.435532604741988 -0.3665049970149996"/>
			<geometry>
				<mesh filename="textured_objs/original-57.obj"/>
			</geometry>
		</collision>
		<collision>
			<origin xyz="0.009567187752129709 0.435532604741988 -0.3665049970149996"/>
			<geometry>
				<mesh filename="textured_objs/original-62.obj"/>
			</geometry>
		</collision>
		<collision>
			<origin xyz="0.009567187752129709 0.435532604741988 -0.3665049970149996"/>
			<geometry>
				<mesh filename="textured_objs/original-49.obj"/>
			</geometry>
		</collision>
		<collision>
			<origin xyz="0.009567187752129709 0.435532604741988 -0.3665049970149996"/>
			<geometry>
				<mesh filename="textured_objs/original-48.obj"/>
			</geometry>
		</collision>
		<collision>
			<origin xyz="0.009567187752129709 0.435532604741988 -0.3665049970149996"/>
			<geometry>
				<mesh filename="textured_objs/original-53.obj"/>
			</geometry>
		</collision>
		<collision>
			<origin xyz="0.009567187752129709 0.435532604741988 -0.3665049970149996"/>
			<geometry>
				<mesh filename="textured_objs/original-55.obj"/>
			</geometry>
		</collision>
		<collision>
			<origin xyz="0.009567187752129709 0.435532604741988 -0.3665049970149996"/>
			<geometry>
				<mesh filename="textured_objs/original-54.obj"/>
			</geometry>
		</collision>
		<collision>
			<origin xyz="0.009567187752129709 0.435532604741988 -0.3665049970149996"/>
			<geometry>
				<mesh filename="textured_objs/original-52.obj"/>
			</geometry>
		</collision>
		<collision>
			<origin xyz="0.009567187752129709 0.435532604741988 -0.3665049970149996"/>
			<geometry>
				<mesh filename="textured_objs/original-51.obj"/>
			</geometry>
		</collision>
		<collision>
			<origin xyz="0.009567187752129709 0.435532604741988 -0.3665049970149996"/>
			<geometry>
				<mesh filename="textured_objs/original-65.obj"/>
			</geometry>
		</collision>
		<collision>
			<origin xyz="0.009567187752129709 0.435532604741988 -0.3665049970149996"/>
			<geometry>
				<mesh filename="textured_objs/original-66.obj"/>
			</geometry>
		</collision>
		<collision>
			<origin xyz="0.009567187752129709 0.435532604741988 -0.3665049970149996"/>
			<geometry>
				<mesh filename="textured_objs/original-67.obj"/>
			</geometry>
		</collision>
		<inertial>
			<origin xyz="0 0 0"/>
			<mass value="0.05"/>
			<inertia ixx="0.001" ixy="0" ixz="0" iyy="0.001" iyz="0" izz="0.001"/>
		</inertial>
	</link>
	<joint name="joint_0" type="prismatic">
		<origin xyz="-0.009567187752129709 -0.435532604741988 0.3665049970149996"/>
		<axis xyz="0 0 1"/>
		<child link="link_0"/>
		<parent link="link_4"/>
		<limit lower="0" upper="0.504"/>
		<dynamics damping="0.1" friction="0.01"/>
	</joint>
	<link name="link_1">
		<visual name="drawer_front-24">
			<origin xyz="0.02519710065310901 0.06335592315963547 0.36449798941612244"/>
			<geometry>
				<mesh filename="textured_objs/original-104.obj"/>
			</geometry>
		</visual>
		<visual name="drawer_front-24">
			<origin xyz="0.02519710065310901 0.06335592315963547 0.36449798941612244"/>
			<geometry>
				<mesh filename="textured_objs/original-107.obj"/>
			</geometry>
		</visual>
		<visual name="drawer_front-24">
			<origin xyz="0.02519710065310901 0.06335592315963547 0.36449798941612244"/>
			<geometry>
				<mesh filename="textured_objs/original-101.obj"/>
			</geometry>
		</visual>
		<visual name="drawer_front-24">
			<origin xyz="0.02519710065310901 0.06335592315963547 0.36449798941612244"/>
			<geometry>
				<mesh filename="textured_objs/original-103.obj"/>
			</geometry>
		</visual>
		<visual name="drawer_front-24">
			<origin xyz="0.02519710065310901 0.06335592315963547 0.36449798941612244"/>
			<geometry>
				<mesh filename="textured_objs/original-102.obj"/>
			</geometry>
		</visual>
		<visual name="drawer_front-24">
			<origin xyz="0.02519710065310901 0.06335592315963547 0.36449798941612244"/>
			<geometry>
				<mesh filename="textured_objs/original-93.obj"/>
			</geometry>
		</visual>
		<visual name="drawer_front-24">
			<origin xyz="0.02519710065310901 0.06335592315963547 0.36449798941612244"/>
			<geometry>
				<mesh filename="textured_objs/original-106.obj"/>
			</geometry>
		</visual>
		<visual name="drawer_side-25">
			<origin xyz="0.02519710065310901 0.06335592315963547 0.36449798941612244"/>
			<geometry>
				<mesh filename="textured_objs/original-92.obj"/>
			</geometry>
		</visual>
		<visual name="drawer_side-26">
			<origin xyz="0.02519710065310901 0.06335592315963547 0.36449798941612244"/>
			<geometry>
				<mesh filename="textured_objs/original-99.obj"/>
			</geometry>
		</visual>
		<visual name="drawer_side-26">
			<origin xyz="0.02519710065310901 0.06335592315963547 0.36449798941612244"/>
			<geometry>
				<mesh filename="textured_objs/original-97.obj"/>
			</geometry>
		</visual>
		<visual name="drawer_back-27">
			<origin xyz="0.02519710065310901 0.06335592315963547 0.36449798941612244"/>
			<geometry>
				<mesh filename="textured_objs/original-98.obj"/>
			</geometry>
		</visual>
		<visual name="drawer_bottom-28">
			<origin xyz="0.02519710065310901 0.06335592315963547 0.36449798941612244"/>
			<geometry>
				<mesh filename="textured_objs/original-96.obj"/>
			</geometry>
		</visual>
		<visual name="drawer_bottom-28">
			<origin xyz="0.02519710065310901 0.06335592315963547 0.36449798941612244"/>
			<geometry>
				<mesh filename="textured_objs/original-95.obj"/>
			</geometry>
		</visual>
		<visual name="handle-23">
			<origin xyz="0.02519710065310901 0.06335592315963547 0.36449798941612244"/>
			<geometry>
				<mesh filename="textured_objs/original-109.obj"/>
			</geometry>
		</visual>
		<visual name="handle-23">
			<origin xyz="0.02519710065310901 0.06335592315963547 0.36449798941612244"/>
			<geometry>
				<mesh filename="textured_objs/original-110.obj"/>
			</geometry>
		</visual>
		<visual name="handle-23">
			<origin xyz="0.02519710065310901 0.06335592315963547 0.36449798941612244"/>
			<geometry>
				<mesh filename="textured_objs/original-111.obj"/>
			</geometry>
		</visual>
		<collision>
			<origin xyz="0.02519710065310901 0.06335592315963547 0.36449798941612244"/>
			<geometry>
				<mesh filename="textured_objs/original-104.obj"/>
			</geometry>
		</collision>
		<collision>
			<origin xyz="0.02519710065310901 0.06335592315963547 0.36449798941612244"/>
			<geometry>
				<mesh filename="textured_objs/original-107.obj"/>
			</geometry>
		</collision>
		<collision>
			<origin xyz="0.02519710065310901 0.06335592315963547 0.36449798941612244"/>
			<geometry>
				<mesh filename="textured_objs/original-101.obj"/>
			</geometry>
		</collision>
		<collision>
			<origin xyz="0.02519710065310901 0.06335592315963547 0.36449798941612244"/>
			<geometry>
				<mesh filename="textured_objs/original-103.obj"/>
			</geometry>
		</collision>
		<collision>
			<origin xyz="0.02519710065310901 0.06335592315963547 0.36449798941612244"/>
			<geometry>
				<mesh filename="textured_objs/original-102.obj"/>
			</geometry>
		</collision>
		<collision>
			<origin xyz="0.02519710065310901 0.06335592315963547 0.36449798941612244"/>
			<geometry>
				<mesh filename="textured_objs/original-93.obj"/>
			</geometry>
		</collision>
		<collision>
			<origin xyz="0.02519710065310901 0.06335592315963547 0.36449798941612244"/>
			<geometry>
				<mesh filename="textured_objs/original-106.obj"/>
			</geometry>
		</collision>
		<collision>
			<origin xyz="0.02519710065310901 0.06335592315963547 0.36449798941612244"/>
			<geometry>
				<mesh filename="textured_objs/original-92.obj"/>
			</geometry>
		</collision>
		<collision>
			<origin xyz="0.02519710065310901 0.06335592315963547 0.36449798941612244"/>
			<geometry>
				<mesh filename="textured_objs/original-99.obj"/>
			</geometry>
		</collision>
		<collision>
			<origin xyz="0.02519710065310901 0.06335592315963547 0.36449798941612244"/>
			<geometry>
				<mesh filename="textured_objs/original-97.obj"/>
			</geometry>
		</collision>
		<collision>
			<origin xyz="0.02519710065310901 0.06335592315963547 0.36449798941612244"/>
			<geometry>
				<mesh filename="textured_objs/original-98.obj"/>
			</geometry>
		</collision>
		<collision>
			<origin xyz="0.02519710065310901 0.06335592315963547 0.36449798941612244"/>
			<geometry>
				<mesh filename="textured_objs/original-96.obj"/>
			</geometry>
		</collision>
		<collision>
			<origin xyz="0.02519710065310901 0.06335592315963547 0.36449798941612244"/>
			<geometry>
				<mesh filename="textured_objs/original-95.obj"/>
			</geometry>
		</collision>
		<collision>
			<origin xyz="0.02519710065310901 0.06335592315963547 0.36449798941612244"/>
			<geometry>
				<mesh filename="textured_objs/original-109.obj"/>
			</geometry>
		</collision>
		<collision>
			<origin xyz="0.02519710065310901 0.06335592315963547 0.36449798941612244"/>
			<geometry>
				<mesh filename="textured_objs/original-110.obj"/>
			</geometry>
		</collision>
		<collision>
			<origin xyz="0.02519710065310901 0.06335592315963547 0.36449798941612244"/>
			<geometry>
				<mesh filename="textured_objs/original-111.obj"/>
			</geometry>
		</collision>
		<inertial>
			<origin xyz="0 0 0"/>
			<mass value="0.05"/>
			<inertia ixx="0.001" ixy="0" ixz="0" iyy="0.001" iyz="0" izz="0.001"/>
		</inertial>
	</link>
	<joint name="joint_1" type="prismatic">
		<origin xyz="-0.02519710065310901 -0.06335592315963547 -0.36449798941612244"/>
		<axis xyz="0 0 1"/>
		<child link="link_1"/>
		<parent link="link_4"/>
		<limit lower="0" upper="0.504"/>
		<dynamics damping="0.1" friction="0.01"/>
	</joint>
	<link name="link_2">
		<visual name="drawer_front-17">
			<origin xyz="-0.002580218835720018 -0.21246546052932785 0.36449798941612244"/>
			<geometry>
				<mesh filename="textured_objs/original-79.obj"/>
			</geometry>
		</visual>
		<visual name="drawer_front-17">
			<origin xyz="-0.002580218835720018 -0.21246546052932785 0.36449798941612244"/>
			<geometry>
				<mesh filename="textured_objs/original-85.obj"/>
			</geometry>
		</visual>
		<visual name="drawer_front-17">
			<origin xyz="-0.002580218835720018 -0.21246546052932785 0.36449798941612244"/>
			<geometry>
				<mesh filename="textured_objs/original-80.obj"/>
			</geometry>
		</visual>
		<visual name="drawer_front-17">
			<origin xyz="-0.002580218835720018 -0.21246546052932785 0.36449798941612244"/>
			<geometry>
				<mesh filename="textured_objs/original-82.obj"/>
			</geometry>
		</visual>
		<visual name="drawer_front-17">
			<origin xyz="-0.002580218835720018 -0.21246546052932785 0.36449798941612244"/>
			<geometry>
				<mesh filename="textured_objs/original-84.obj"/>
			</geometry>
		</visual>
		<visual name="drawer_front-17">
			<origin xyz="-0.002580218835720018 -0.21246546052932785 0.36449798941612244"/>
			<geometry>
				<mesh filename="textured_objs/original-81.obj"/>
			</geometry>
		</visual>
		<visual name="drawer_front-17">
			<origin xyz="-0.002580218835720018 -0.21246546052932785 0.36449798941612244"/>
			<geometry>
				<mesh filename="textured_objs/original-71.obj"/>
			</geometry>
		</visual>
		<visual name="drawer_side-18">
			<origin xyz="-0.002580218835720018 -0.21246546052932785 0.36449798941612244"/>
			<geometry>
				<mesh filename="textured_objs/original-75.obj"/>
			</geometry>
		</visual>
		<visual name="drawer_side-18">
			<origin xyz="-0.002580218835720018 -0.21246546052932785 0.36449798941612244"/>
			<geometry>
				<mesh filename="textured_objs/original-77.obj"/>
			</geometry>
		</visual>
		<visual name="drawer_side-19">
			<origin xyz="-0.002580218835720018 -0.21246546052932785 0.36449798941612244"/>
			<geometry>
				<mesh filename="textured_objs/original-70.obj"/>
			</geometry>
		</visual>
		<visual name="drawer_back-20">
			<origin xyz="-0.002580218835720018 -0.21246546052932785 0.36449798941612244"/>
			<geometry>
				<mesh filename="textured_objs/original-76.obj"/>
			</geometry>
		</visual>
		<visual name="drawer_bottom-21">
			<origin xyz="-0.002580218835720018 -0.21246546052932785 0.36449798941612244"/>
			<geometry>
				<mesh filename="textured_objs/original-74.obj"/>
			</geometry>
		</visual>
		<visual name="drawer_bottom-21">
			<origin xyz="-0.002580218835720018 -0.21246546052932785 0.36449798941612244"/>
			<geometry>
				<mesh filename="textured_objs/original-73.obj"/>
			</geometry>
		</visual>
		<visual name="handle-16">
			<origin xyz="-0.002580218835720018 -0.21246546052932785 0.36449798941612244"/>
			<geometry>
				<mesh filename="textured_objs/original-87.obj"/>
			</geometry>
		</visual>
		<visual name="handle-16">
			<origin xyz="-0.002580218835720018 -0.21246546052932785 0.36449798941612244"/>
			<geometry>
				<mesh filename="textured_objs/original-88.obj"/>
			</geometry>
		</visual>
		<visual name="handle-16">
			<origin xyz="-0.002580218835720018 -0.21246546052932785 0.36449798941612244"/>
			<geometry>
				<mesh filename="textured_objs/original-89.obj"/>
			</geometry>
		</visual>
		<collision>
			<origin xyz="-0.002580218835720018 -0.21246546052932785 0.36449798941612244"/>
			<geometry>
				<mesh filename="textured_objs/original-79.obj"/>
			</geometry>
		</collision>
		<collision>
			<origin xyz="-0.002580218835720018 -0.21246546052932785 0.36449798941612244"/>
			<geometry>
				<mesh filename="textured_objs/original-85.obj"/>
			</geometry>
		</collision>
		<collision>
			<origin xyz="-0.002580218835720018 -0.21246546052932785 0.36449798941612244"/>
			<geometry>
				<mesh filename="textured_objs/original-80.obj"/>
			</geometry>
		</collision>
		<collision>
			<origin xyz="-0.002580218835720018 -0.21246546052932785 0.36449798941612244"/>
			<geometry>
				<mesh filename="textured_objs/original-82.obj"/>
			</geometry>
		</collision>
		<collision>
			<origin xyz="-0.002580218835720018 -0.21246546052932785 0.36449798941612244"/>
			<geometry>
				<mesh filename="textured_objs/original-84.obj"/>
			</geometry>
		</collision>
		<collision>
			<origin xyz="-0.002580218835720018 -0.21246546052932785 0.36449798941612244"/>
			<geometry>
				<mesh filename="textured_objs/original-81.obj"/>
			</geometry>
		</collision>
		<collision>
			<origin xyz="-0.002580218835720018 -0.21246546052932785 0.36449798941612244"/>
			<geometry>
				<mesh filename="textured_objs/original-71.obj"/>
			</geometry>
		</collision>
		<collision>
			<origin xyz="-0.002580218835720018 -0.21246546052932785 0.36449798941612244"/>
			<geometry>
				<mesh filename="textured_objs/original-75.obj"/>
			</geometry>
		</collision>
		<collision>
			<origin xyz="-0.002580218835720018 -0.21246546052932785 0.36449798941612244"/>
			<geometry>
				<mesh filename="textured_objs/original-77.obj"/>
			</geometry>
		</collision>
		<collision>
			<origin xyz="-0.002580218835720018 -0.21246546052932785 0.36449798941612244"/>
			<geometry>
				<mesh filename="textured_objs/original-70.obj"/>
			</geometry>
		</collision>
		<collision>
			<origin xyz="-0.002580218835720018 -0.21246546052932785 0.36449798941612244"/>
			<geometry>
				<mesh filename="textured_objs/original-76.obj"/>
			</geometry>
		</collision>
		<collision>
			<origin xyz="-0.002580218835720018 -0.21246546052932785 0.36449798941612244"/>
			<geometry>
				<mesh filename="textured_objs/original-74.obj"/>
			</geometry>
		</collision>
		<collision>
			<origin xyz="-0.002580218835720018 -0.21246546052932785 0.36449798941612244"/>
			<geometry>
				<mesh filename="textured_objs/original-73.obj"/>
			</geometry>
		</collision>
		<collision>
			<origin xyz="-0.002580218835720018 -0.21246546052932785 0.36449798941612244"/>
			<geometry>
				<mesh filename="textured_objs/original-87.obj"/>
			</geometry>
		</collision>
		<collision>
			<origin xyz="-0.002580218835720018 -0.21246546052932785 0.36449798941612244"/>
			<geometry>
				<mesh filename="textured_objs/original-88.obj"/>
			</geometry>
		</collision>
		<collision>
			<origin xyz="-0.002580218835720018 -0.21246546052932785 0.36449798941612244"/>
			<geometry>
				<mesh filename="textured_objs/original-89.obj"/>
			</geometry>
		</collision>
		<inertial>
			<origin xyz="0 0 0"/>
			<mass value="0.05"/>
			<inertia ixx="0.001" ixy="0" ixz="0" iyy="0.001" iyz="0" izz="0.001"/>
		</inertial>
	</link>
	<joint name="joint_2" type="prismatic">
		<origin xyz="0.002580218835720018 0.21246546052932785 -0.36449798941612244"/>
		<axis xyz="0 0 1"/>
		<child link="link_2"/>
		<parent link="link_4"/>
		<limit lower="0" upper="0.504"/>
		<dynamics damping="0.1" friction="0.01"/>
	</joint>
	<link name="link_3">
		<visual name="drawer_front-10">
			<origin xyz="-0.006071405476377854 -0.48437233339913544 0.36449798941612244"/>
			<geometry>
				<mesh filename="textured_objs/original-35.obj"/>
			</geometry>
		</visual>
		<visual name="drawer_front-10">
			<origin xyz="-0.006071405476377854 -0.48437233339913544 0.36449798941612244"/>
			<geometry>
				<mesh filename="textured_objs/original-41.obj"/>
			</geometry>
		</visual>
		<visual name="drawer_front-10">
			<origin xyz="-0.006071405476377854 -0.48437233339913544 0.36449798941612244"/>
			<geometry>
				<mesh filename="textured_objs/original-37.obj"/>
			</geometry>
		</visual>
		<visual name="drawer_front-10">
			<origin xyz="-0.006071405476377854 -0.48437233339913544 0.36449798941612244"/>
			<geometry>
				<mesh filename="textured_objs/original-38.obj"/>
			</geometry>
		</visual>
		<visual name="drawer_front-10">
			<origin xyz="-0.006071405476377854 -0.48437233339913544 0.36449798941612244"/>
			<geometry>
				<mesh filename="textured_objs/original-36.obj"/>
			</geometry>
		</visual>
		<visual name="drawer_front-10">
			<origin xyz="-0.006071405476377854 -0.48437233339913544 0.36449798941612244"/>
			<geometry>
				<mesh filename="textured_objs/original-27.obj"/>
			</geometry>
		</visual>
		<visual name="drawer_front-10">
			<origin xyz="-0.006071405476377854 -0.48437233339913544 0.36449798941612244"/>
			<geometry>
				<mesh filename="textured_objs/original-40.obj"/>
			</geometry>
		</visual>
		<visual name="drawer_side-11">
			<origin xyz="-0.006071405476377854 -0.48437233339913544 0.36449798941612244"/>
			<geometry>
				<mesh filename="textured_objs/original-31.obj"/>
			</geometry>
		</visual>
		<visual name="drawer_side-11">
			<origin xyz="-0.006071405476377854 -0.48437233339913544 0.36449798941612244"/>
			<geometry>
				<mesh filename="textured_objs/original-33.obj"/>
			</geometry>
		</visual>
		<visual name="drawer_side-12">
			<origin xyz="-0.006071405476377854 -0.48437233339913544 0.36449798941612244"/>
			<geometry>
				<mesh filename="textured_objs/original-26.obj"/>
			</geometry>
		</visual>
		<visual name="drawer_back-13">
			<origin xyz="-0.006071405476377854 -0.48437233339913544 0.36449798941612244"/>
			<geometry>
				<mesh filename="textured_objs/original-32.obj"/>
			</geometry>
		</visual>
		<visual name="drawer_bottom-14">
			<origin xyz="-0.006071405476377854 -0.48437233339913544 0.36449798941612244"/>
			<geometry>
				<mesh filename="textured_objs/original-30.obj"/>
			</geometry>
		</visual>
		<visual name="drawer_bottom-14">
			<origin xyz="-0.006071405476377854 -0.48437233339913544 0.36449798941612244"/>
			<geometry>
				<mesh filename="textured_objs/original-29.obj"/>
			</geometry>
		</visual>
		<visual name="handle-9">
			<origin xyz="-0.006071405476377854 -0.48437233339913544 0.36449798941612244"/>
			<geometry>
				<mesh filename="textured_objs/original-43.obj"/>
			</geometry>
		</visual>
		<visual name="handle-9">
			<origin xyz="-0.006071405476377854 -0.48437233339913544 0.36449798941612244"/>
			<geometry>
				<mesh filename="textured_objs/original-44.obj"/>
			</geometry>
		</visual>
		<visual name="handle-9">
			<origin xyz="-0.006071405476377854 -0.48437233339913544 0.36449798941612244"/>
			<geometry>
				<mesh filename="textured_objs/original-45.obj"/>
			</geometry>
		</visual>
		<collision>
			<origin xyz="-0.006071405476377854 -0.48437233339913544 0.36449798941612244"/>
			<geometry>
				<mesh filename="textured_objs/original-35.obj"/>
			</geometry>
		</collision>
		<collision>
			<origin xyz="-0.006071405476377854 -0.48437233339913544 0.36449798941612244"/>
			<geometry>
				<mesh filename="textured_objs/original-41.obj"/>
			</geometry>
		</collision>
		<collision>
			<origin xyz="-0.006071405476377854 -0.48437233339913544 0.36449798941612244"/>
			<geometry>
				<mesh filename="textured_objs/original-37.obj"/>
			</geometry>
		</collision>
		<collision>
			<origin xyz="-0.006071405476377854 -0.48437233339913544 0.36449798941612244"/>
			<geometry>
				<mesh filename="textured_objs/original-38.obj"/>
			</geometry>
		</collision>
		<collision>
			<origin xyz="-0.006071405476377854 -0.48437233339913544 0.36449798941612244"/>
			<geometry>
				<mesh filename="textured_objs/original-36.obj"/>
			</geometry>
		</collision>
		<collision>
			<origin xyz="-0.006071405476377854 -0.48437233339913544 0.36449798941612244"/>
			<geometry>
				<mesh filename="textured_objs/original-27.obj"/>
			</geometry>
		</collision>
		<collision>
			<origin xyz="-0.006071405476377854 -0.48437233339913544 0.36449798941612244"/>
			<geometry>
				<mesh filename="textured_objs/original-40.obj"/>
			</geometry>
		</collision>
		<collision>
			<origin xyz="-0.006071405476377854 -0.48437233339913544 0.36449798941612244"/>
			<geometry>
				<mesh filename="textured_objs/original-31.obj"/>
			</geometry>
		</collision>
		<collision>
			<origin xyz="-0.006071405476377854 -0.48437233339913544 0.36449798941612244"/>
			<geometry>
				<mesh filename="textured_objs/original-33.obj"/>
			</geometry>
		</collision>
		<collision>
			<origin xyz="-0.006071405476377854 -0.48437233339913544 0.36449798941612244"/>
			<geometry>
				<mesh filename="textured_objs/original-26.obj"/>
			</geometry>
		</collision>
		<collision>
			<origin xyz="-0.006071405476377854 -0.48437233339913544 0.36449798941612244"/>
			<geometry>
				<mesh filename="textured_objs/original-32.obj"/>
			</geometry>
		</collision>
		<collision>
			<origin xyz="-0.006071405476377854 -0.48437233339913544 0.36449798941612244"/>
			<geometry>
				<mesh filename="textured_objs/original-30.obj"/>
			</geometry>
		</collision>
		<collision>
			<origin xyz="-0.006071405476377854 -0.48437233339913544 0.36449798941612244"/>
			<geometry>
				<mesh filename="textured_objs/original-29.obj"/>
			</geometry>
		</collision>
		<collision>
			<origin xyz="-0.006071405476377854 -0.48437233339913544 0.36449798941612244"/>
			<geometry>
				<mesh filename="textured_objs/original-43.obj"/>
			</geometry>
		</collision>
		<collision>
			<origin xyz="-0.006071405476377854 -0.48437233339913544 0.36449798941612244"/>
			<geometry>
				<mesh filename="textured_objs/original-44.obj"/>
			</geometry>
		</collision>
		<collision>
			<origin xyz="-0.006071405476377854 -0.48437233339913544 0.36449798941612244"/>
			<geometry>
				<mesh filename="textured_objs/original-45.obj"/>
			</geometry>
		</collision>
		<inertial>
			<origin xyz="0 0 0"/>
			<mass value="0.05"/>
			<inertia ixx="0.001" ixy="0" ixz="0" iyy="0.001" iyz="0" izz="0.001"/>
		</inertial>
	</link>
	<joint name="joint_3" type="prismatic">
		<origin xyz="0.006071405476377854 0.48437233339913544 -0.36449798941612244"/>
		<axis xyz="0 0 1"/>
		<child link="link_3"/>
		<parent link="link_4"/>
		<limit lower="0" upper="0.504"/>
		<dynamics damping="0.1" friction="0.01"/>
	</joint>
	<link name="link_4">
		<visual name="vertical_side_panel-41">
			<origin xyz="0 0 0"/>
			<geometry>
				<mesh filename="textured_objs/original-11.obj"/>
			</geometry>
		</visual>
		<visual name="vertical_side_panel-41">
			<origin xyz="0 0 0"/>
			<geometry>
				<mesh filename="textured_objs/original-10.obj"/>
			</geometry>
		</visual>
		<visual name="vertical_side_panel-42">
			<origin xyz="0 0 0"/>
			<geometry>
				<mesh filename="textured_objs/original-15.obj"/>
			</geometry>
		</visual>
		<visual name="vertical_side_panel-42">
			<origin xyz="0 0 0"/>
			<geometry>
				<mesh filename="textured_objs/original-14.obj"/>
			</geometry>
		</visual>
		<visual name="back_panel-43">
			<origin xyz="0 0 0"/>
			<geometry>
				<mesh filename="textured_objs/original-5.obj"/>
			</geometry>
		</visual>
		<visual name="bottom_panel-44">
			<origin xyz="0 0 0"/>
			<geometry>
				<mesh filename="textured_objs/original-2.obj"/>
			</geometry>
		</visual>
		<visual name="frame_vertical_bar-45">
			<origin xyz="0 0 0"/>
			<geometry>
				<mesh filename="textured_objs/original-3.obj"/>
			</geometry>
		</visual>
		<visual name="frame_vertical_bar-46">
			<origin xyz="0 0 0"/>
			<geometry>
				<mesh filename="textured_objs/original-7.obj"/>
			</geometry>
		</visual>
		<visual name="frame_horizontal_bar-47">
			<origin xyz="0 0 0"/>
			<geometry>
				<mesh filename="textured_objs/original-21.obj"/>
			</geometry>
		</visual>
		<visual name="frame_horizontal_bar-48">
			<origin xyz="0 0 0"/>
			<geometry>
				<mesh filename="textured_objs/original-20.obj"/>
			</geometry>
		</visual>
		<visual name="frame_horizontal_bar-49">
			<origin xyz="0 0 0"/>
			<geometry>
				<mesh filename="textured_objs/original-8.obj"/>
			</geometry>
		</visual>
		<visual name="frame_horizontal_bar-50">
			<origin xyz="0 0 0"/>
			<geometry>
				<mesh filename="textured_objs/original-23.obj"/>
			</geometry>
		</visual>
		<visual name="frame_horizontal_bar-51">
			<origin xyz="0 0 0"/>
			<geometry>
				<mesh filename="textured_objs/original-22.obj"/>
			</geometry>
		</visual>
		<visual name="frame_horizontal_bar-52">
			<origin xyz="0 0 0"/>
			<geometry>
				<mesh filename="textured_objs/original-17.obj"/>
			</geometry>
		</visual>
		<visual name="frame_horizontal_bar-53">
			<origin xyz="0 0 0"/>
			<geometry>
				<mesh filename="textured_objs/original-6.obj"/>
			</geometry>
		</visual>
		<visual name="frame_horizontal_bar-54">
			<origin xyz="0 0 0"/>
			<geometry>
				<mesh filename="textured_objs/original-4.obj"/>
			</geometry>
		</visual>
		<visual name="other_leaf-56">
			<origin xyz="0 0 0"/>
			<geometry>
				<mesh filename="textured_objs/original-112.obj"/>
			</geometry>
		</visual>
		<visual name="base_side_panel-37">
			<origin xyz="0 0 0"/>
			<geometry>
				<mesh filename="textured_objs/original-12.obj"/>
			</geometry>
		</visual>
		<visual name="base_side_panel-38">
			<origin xyz="0 0 0"/>
			<geometry>
				<mesh filename="textured_objs/original-18.obj"/>
			</geometry>
		</visual>
		<visual name="base_side_panel-39">
			<origin xyz="0 0 0"/>
			<geometry>
				<mesh filename="textured_objs/original-16.obj"/>
			</geometry>
		</visual>
		<visual name="base_side_panel-40">
			<origin xyz="0 0 0"/>
			<geometry>
				<mesh filename="textured_objs/original-19.obj"/>
			</geometry>
		</visual>
		<collision>
			<origin xyz="0 0 0"/>
			<geometry>
				<mesh filename="textured_objs/original-11.obj"/>
			</geometry>
		</collision>
		<collision>
			<origin xyz="0 0 0"/>
			<geometry>
				<mesh filename="textured_objs/original-10.obj"/>
			</geometry>
		</collision>
		<collision>
			<origin xyz="0 0 0"/>
			<geometry>
				<mesh filename="textured_objs/original-15.obj"/>
			</geometry>
		</collision>
		<collision>
			<origin xyz="0 0 0"/>
			<geometry>
				<mesh filename="textured_objs/original-14.obj"/>
			</geometry>
		</collision>
		<collision>
			<origin xyz="0 0 0"/>
			<geometry>
				<mesh filename="textured_objs/original-5.obj"/>
			</geometry>
		</collision>
		<collision>
			<origin xyz="0 0 0"/>
			<geometry>
				<mesh filename="textured_objs/original-2.obj"/>
			</geometry>
		</collision>
		<collision>
			<origin xyz="0 0 0"/>
			<geometry>
				<mesh filename="textured_objs/original-3.obj"/>
			</geometry>
		</collision>
		<collision>
			<origin xyz="0 0 0"/>
			<geometry>
				<mesh filename="textured_objs/original-7.obj"/>
			</geometry>
		</collision>
		<collision>
			<origin xyz="0 0 0"/>
			<geometry>
				<mesh filename="textured_objs/original-21.obj"/>
			</geometry>
		</collision>
		<collision>
			<origin xyz="0 0 0"/>
			<geometry>
				<mesh filename="textured_objs/original-20.obj"/>
			</geometry>
		</collision>
		<collision>
			<origin xyz="0 0 0"/>
			<geometry>
				<mesh filename="textured_objs/original-8.obj"/>
			</geometry>
		</collision>
		<collision>
			<origin xyz="0 0 0"/>
			<geometry>
				<mesh filename="textured_objs/original-23.obj"/>
			</geometry>
		</collision>
		<collision>
			<origin xyz="0 0 0"/>
			<geometry>
				<mesh filename="textured_objs/original-22.obj"/>
			</geometry>
		</collision>
		<collision>
			<origin xyz="0 0 0"/>
			<geometry>
				<mesh filename="textured_objs/original-17.obj"/>
			</geometry>
		</collision>
		<collision>
			<origin xyz="0 0 0"/>
			<geometry>
				<mesh filename="textured_objs/original-6.obj"/>
			</geometry>
		</collision>
		<collision>
			<origin xyz="0 0 0"/>
			<geometry>
				<mesh filename="textured_objs/original-4.obj"/>
			</geometry>
		</collision>
		<collision>
			<origin xyz="0 0 0"/>
			<geometry>
				<mesh filename="textured_objs/original-112.obj"/>
			</geometry>
		</collision>
		<collision>
			<origin xyz="0 0 0"/>
			<geometry>
				<mesh filename="textured_objs/original-12.obj"/>
			</geometry>
		</collision>
		<collision>
			<origin xyz="0 0 0"/>
			<geometry>
				<mesh filename="textured_objs/original-18.obj"/>
			</geometry>
		</collision>
		<collision>
			<origin xyz="0 0 0"/>
			<geometry>
				<mesh filename="textured_objs/original-16.obj"/>
			</geometry>
		</collision>
		<collision>
			<origin xyz="0 0 0"/>
			<geometry>
				<mesh filename="textured_objs/original-19.obj"/>
			</geometry>
		</collision>
		<inertial>
			<origin xyz="0 0 0"/>
			<mass value="2.0"/>
			<inertia ixx="0.01" ixy="0" ixz="0" iyy="0.01" iyz="0" izz="0.01"/>
		</inertial>
	</link>
	<joint name="joint_4" type="fixed">
		<origin rpy="1.570796326794897 0 -1.570796326794897" xyz="0 0 0"/>
		<child link="link_4"/>
		<parent link="base"/>
	</joint>
</robot>
